[2021-09-01 13:33:33 +0100] [10029] [INFO] Starting gunicorn 20.1.0
[2021-09-01 13:33:33 +0100] [10029] [INFO] Listening at: https://0.0.0.0:5000 (10029)
[2021-09-01 13:33:33 +0100] [10029] [INFO] Using worker: sync
[2021-09-01 13:33:33 +0100] [10041] [INFO] Booting worker with pid: 10041
[2021-09-01 13:33:33 +0100] [10042] [INFO] Booting worker with pid: 10042
[2021-09-01 13:33:34 +0100] [10043] [INFO] Booting worker with pid: 10043
[2021-09-01 13:33:34 +0100] [10044] [INFO] Booting worker with pid: 10044
[2021-09-01 13:47:28 +0100] [10029] [INFO] Handling signal: int
[2021-09-01 13:47:28 +0100] [10041] [INFO] Worker exiting (pid: 10041)
[2021-09-01 13:47:28 +0100] [10044] [INFO] Worker exiting (pid: 10044)
[2021-09-01 13:47:28 +0100] [10042] [INFO] Worker exiting (pid: 10042)
[2021-09-01 13:47:28 +0100] [10043] [INFO] Worker exiting (pid: 10043)
[2021-09-01 13:47:29 +0100] [10029] [WARNING] Worker with pid 10043 was terminated due to signal 2
[2021-09-01 13:47:29 +0100] [10029] [WARNING] Worker with pid 10041 was terminated due to signal 2
[2021-09-01 13:47:29 +0100] [10029] [WARNING] Worker with pid 10044 was terminated due to signal 2
[2021-09-01 13:47:29 +0100] [10029] [WARNING] Worker with pid 10042 was terminated due to signal 2
[2021-09-01 13:47:29 +0100] [10029] [INFO] Shutting down: Master
[2021-09-01 13:48:02 +0000] [11233] [INFO] Starting gunicorn 19.9.0
[2021-09-01 13:48:02 +0000] [11233] [ERROR] Retrying in 1 second.
[2021-09-01 13:48:03 +0000] [11233] [ERROR] Retrying in 1 second.
[2021-09-01 13:48:04 +0000] [11233] [ERROR] Retrying in 1 second.
[2021-09-01 13:48:05 +0000] [11233] [ERROR] Retrying in 1 second.
[2021-09-01 13:48:06 +0000] [11233] [ERROR] Retrying in 1 second.
[2021-09-01 13:48:07 +0000] [11233] [ERROR] Can't connect to /var/www/application.sock
[2021-09-01 13:48:19 +0000] [11253] [INFO] Starting gunicorn 19.9.0
[2021-09-01 13:48:19 +0000] [11253] [ERROR] Retrying in 1 second.
[2021-09-01 13:48:20 +0000] [11253] [ERROR] Retrying in 1 second.
[2021-09-01 13:48:21 +0000] [11253] [ERROR] Retrying in 1 second.
[2021-09-01 13:48:22 +0000] [11253] [ERROR] Retrying in 1 second.
[2021-09-01 13:48:23 +0000] [11253] [ERROR] Retrying in 1 second.
[2021-09-01 13:48:24 +0000] [11253] [ERROR] Can't connect to /var/www/application.sock
[2021-09-01 13:49:25 +0000] [11294] [INFO] Starting gunicorn 19.9.0
[2021-09-01 13:49:25 +0000] [11294] [ERROR] Retrying in 1 second.
[2021-09-01 13:49:26 +0000] [11294] [ERROR] Retrying in 1 second.
[2021-09-01 13:49:27 +0000] [11294] [ERROR] Retrying in 1 second.
[2021-09-01 13:49:28 +0000] [11294] [ERROR] Retrying in 1 second.
[2021-09-01 13:49:29 +0000] [11294] [ERROR] Retrying in 1 second.
[2021-09-01 13:49:30 +0000] [11294] [ERROR] Can't connect to /var/www/application.sock
[2021-09-01 14:28:15 +0000] [12127] [INFO] Starting gunicorn 19.9.0
[2021-09-01 14:28:16 +0000] [12127] [INFO] Listening at: unix:app.sock (12127)
[2021-09-01 14:28:16 +0000] [12127] [INFO] Using worker: sync
[2021-09-01 14:28:16 +0000] [12131] [INFO] Booting worker with pid: 12131
[2021-09-01 14:28:16 +0000] [12132] [INFO] Booting worker with pid: 12132
[2021-09-01 14:28:16 +0000] [12131] [ERROR] Exception in worker process
Traceback (most recent call last):
  File "/usr/lib/python2.7/dist-packages/gunicorn/arbiter.py", line 583, in spawn_worker
    worker.init_process()
  File "/usr/lib/python2.7/dist-packages/gunicorn/workers/base.py", line 129, in init_process
    self.load_wsgi()
  File "/usr/lib/python2.7/dist-packages/gunicorn/workers/base.py", line 138, in load_wsgi
    self.wsgi = self.app.wsgi()
  File "/usr/lib/python2.7/dist-packages/gunicorn/app/base.py", line 67, in wsgi
    self.callable = self.load()
  File "/usr/lib/python2.7/dist-packages/gunicorn/app/wsgiapp.py", line 52, in load
    return self.load_wsgiapp()
  File "/usr/lib/python2.7/dist-packages/gunicorn/app/wsgiapp.py", line 41, in load_wsgiapp
    return util.import_app(self.app_uri)
  File "/usr/lib/python2.7/dist-packages/gunicorn/util.py", line 375, in import_app
    __import__(module)
  File "/home/pi/wanderpi/app.py", line 1, in <module>
    from controller.modules.home.geocode_utils import GeoCodeUtils
  File "/home/pi/wanderpi/controller/__init__.py", line 3, in <module>
    from flask import Flask
ImportError: No module named flask
[2021-09-01 14:28:16 +0000] [12132] [ERROR] Exception in worker process
Traceback (most recent call last):
  File "/usr/lib/python2.7/dist-packages/gunicorn/arbiter.py", line 583, in spawn_worker
    worker.init_process()
  File "/usr/lib/python2.7/dist-packages/gunicorn/workers/base.py", line 129, in init_process
    self.load_wsgi()
  File "/usr/lib/python2.7/dist-packages/gunicorn/workers/base.py", line 138, in load_wsgi
    self.wsgi = self.app.wsgi()
  File "/usr/lib/python2.7/dist-packages/gunicorn/app/base.py", line 67, in wsgi
    self.callable = self.load()
  File "/usr/lib/python2.7/dist-packages/gunicorn/app/wsgiapp.py", line 52, in load
    return self.load_wsgiapp()
  File "/usr/lib/python2.7/dist-packages/gunicorn/app/wsgiapp.py", line 41, in load_wsgiapp
    return util.import_app(self.app_uri)
  File "/usr/lib/python2.7/dist-packages/gunicorn/util.py", line 375, in import_app
    __import__(module)
  File "/home/pi/wanderpi/app.py", line 1, in <module>
    from controller.modules.home.geocode_utils import GeoCodeUtils
  File "/home/pi/wanderpi/controller/__init__.py", line 3, in <module>
    from flask import Flask
ImportError: No module named flask
[2021-09-01 14:28:16 +0000] [12131] [INFO] Worker exiting (pid: 12131)
[2021-09-01 14:28:16 +0000] [12132] [INFO] Worker exiting (pid: 12132)
[2021-09-01 14:28:16 +0000] [12133] [INFO] Booting worker with pid: 12133
[2021-09-01 14:28:16 +0000] [12133] [ERROR] Exception in worker process
Traceback (most recent call last):
  File "/usr/lib/python2.7/dist-packages/gunicorn/arbiter.py", line 583, in spawn_worker
    worker.init_process()
  File "/usr/lib/python2.7/dist-packages/gunicorn/workers/base.py", line 129, in init_process
    self.load_wsgi()
  File "/usr/lib/python2.7/dist-packages/gunicorn/workers/base.py", line 138, in load_wsgi
    self.wsgi = self.app.wsgi()
  File "/usr/lib/python2.7/dist-packages/gunicorn/app/base.py", line 67, in wsgi
    self.callable = self.load()
  File "/usr/lib/python2.7/dist-packages/gunicorn/app/wsgiapp.py", line 52, in load
    return self.load_wsgiapp()
  File "/usr/lib/python2.7/dist-packages/gunicorn/app/wsgiapp.py", line 41, in load_wsgiapp
    return util.import_app(self.app_uri)
  File "/usr/lib/python2.7/dist-packages/gunicorn/util.py", line 375, in import_app
    __import__(module)
  File "/home/pi/wanderpi/app.py", line 1, in <module>
    from controller.modules.home.geocode_utils import GeoCodeUtils
  File "/home/pi/wanderpi/controller/__init__.py", line 3, in <module>
    from flask import Flask
ImportError: No module named flask
[2021-09-01 14:28:16 +0000] [12133] [INFO] Worker exiting (pid: 12133)
[2021-09-01 14:28:16 +0000] [12127] [INFO] Shutting down: Master
[2021-09-01 14:28:16 +0000] [12127] [INFO] Reason: Worker failed to boot.
[2021-09-01 14:28:41 +0000] [12150] [INFO] Starting gunicorn 19.9.0
[2021-09-01 14:28:41 +0000] [12150] [INFO] Listening at: unix:app.sock (12150)
[2021-09-01 14:28:41 +0000] [12150] [INFO] Using worker: sync
[2021-09-01 14:28:41 +0000] [12154] [INFO] Booting worker with pid: 12154
[2021-09-01 14:28:41 +0000] [12154] [ERROR] Exception in worker process
Traceback (most recent call last):
  File "/usr/lib/python2.7/dist-packages/gunicorn/arbiter.py", line 583, in spawn_worker
    worker.init_process()
  File "/usr/lib/python2.7/dist-packages/gunicorn/workers/base.py", line 129, in init_process
    self.load_wsgi()
  File "/usr/lib/python2.7/dist-packages/gunicorn/workers/base.py", line 138, in load_wsgi
    self.wsgi = self.app.wsgi()
  File "/usr/lib/python2.7/dist-packages/gunicorn/app/base.py", line 67, in wsgi
    self.callable = self.load()
  File "/usr/lib/python2.7/dist-packages/gunicorn/app/wsgiapp.py", line 52, in load
    return self.load_wsgiapp()
  File "/usr/lib/python2.7/dist-packages/gunicorn/app/wsgiapp.py", line 41, in load_wsgiapp
    return util.import_app(self.app_uri)
  File "/usr/lib/python2.7/dist-packages/gunicorn/util.py", line 375, in import_app
    __import__(module)
  File "/home/pi/wanderpi/app.py", line 1, in <module>
    from controller.modules.home.geocode_utils import GeoCodeUtils
  File "/home/pi/wanderpi/controller/__init__.py", line 3, in <module>
    from flask import Flask
ImportError: No module named flask
[2021-09-01 14:28:41 +0000] [12154] [INFO] Worker exiting (pid: 12154)
[2021-09-01 14:28:41 +0000] [12155] [INFO] Booting worker with pid: 12155
[2021-09-01 14:28:41 +0000] [12155] [ERROR] Exception in worker process
Traceback (most recent call last):
  File "/usr/lib/python2.7/dist-packages/gunicorn/arbiter.py", line 583, in spawn_worker
    worker.init_process()
  File "/usr/lib/python2.7/dist-packages/gunicorn/workers/base.py", line 129, in init_process
    self.load_wsgi()
  File "/usr/lib/python2.7/dist-packages/gunicorn/workers/base.py", line 138, in load_wsgi
    self.wsgi = self.app.wsgi()
  File "/usr/lib/python2.7/dist-packages/gunicorn/app/base.py", line 67, in wsgi
    self.callable = self.load()
  File "/usr/lib/python2.7/dist-packages/gunicorn/app/wsgiapp.py", line 52, in load
    return self.load_wsgiapp()
  File "/usr/lib/python2.7/dist-packages/gunicorn/app/wsgiapp.py", line 41, in load_wsgiapp
    return util.import_app(self.app_uri)
  File "/usr/lib/python2.7/dist-packages/gunicorn/util.py", line 375, in import_app
    __import__(module)
  File "/home/pi/wanderpi/app.py", line 1, in <module>
    from controller.modules.home.geocode_utils import GeoCodeUtils
  File "/home/pi/wanderpi/controller/__init__.py", line 3, in <module>
    from flask import Flask
ImportError: No module named flask
[2021-09-01 14:28:41 +0000] [12155] [INFO] Worker exiting (pid: 12155)
[2021-09-01 14:28:41 +0000] [12156] [INFO] Booting worker with pid: 12156
[2021-09-01 14:28:41 +0000] [12156] [ERROR] Exception in worker process
Traceback (most recent call last):
  File "/usr/lib/python2.7/dist-packages/gunicorn/arbiter.py", line 583, in spawn_worker
    worker.init_process()
  File "/usr/lib/python2.7/dist-packages/gunicorn/workers/base.py", line 129, in init_process
    self.load_wsgi()
  File "/usr/lib/python2.7/dist-packages/gunicorn/workers/base.py", line 138, in load_wsgi
    self.wsgi = self.app.wsgi()
  File "/usr/lib/python2.7/dist-packages/gunicorn/app/base.py", line 67, in wsgi
    self.callable = self.load()
  File "/usr/lib/python2.7/dist-packages/gunicorn/app/wsgiapp.py", line 52, in load
    return self.load_wsgiapp()
  File "/usr/lib/python2.7/dist-packages/gunicorn/app/wsgiapp.py", line 41, in load_wsgiapp
    return util.import_app(self.app_uri)
  File "/usr/lib/python2.7/dist-packages/gunicorn/util.py", line 375, in import_app
    __import__(module)
  File "/home/pi/wanderpi/app.py", line 1, in <module>
    from controller.modules.home.geocode_utils import GeoCodeUtils
  File "/home/pi/wanderpi/controller/__init__.py", line 3, in <module>
    from flask import Flask
ImportError: No module named flask
[2021-09-01 14:28:41 +0000] [12156] [INFO] Worker exiting (pid: 12156)
[2021-09-01 14:28:41 +0000] [12150] [INFO] Shutting down: Master
[2021-09-01 14:28:41 +0000] [12150] [INFO] Reason: Worker failed to boot.
[2021-09-01 14:30:00 +0000] [12184] [INFO] Starting gunicorn 19.9.0
[2021-09-01 14:30:00 +0000] [12184] [INFO] Listening at: unix:app.sock (12184)
[2021-09-01 14:30:00 +0000] [12184] [INFO] Using worker: sync
[2021-09-01 14:30:00 +0000] [12188] [INFO] Booting worker with pid: 12188
[2021-09-01 14:30:00 +0000] [12189] [INFO] Booting worker with pid: 12189
[2021-09-01 14:30:00 +0000] [12188] [ERROR] Exception in worker process
Traceback (most recent call last):
  File "/usr/lib/python2.7/dist-packages/gunicorn/arbiter.py", line 583, in spawn_worker
    worker.init_process()
  File "/usr/lib/python2.7/dist-packages/gunicorn/workers/base.py", line 129, in init_process
    self.load_wsgi()
  File "/usr/lib/python2.7/dist-packages/gunicorn/workers/base.py", line 138, in load_wsgi
    self.wsgi = self.app.wsgi()
  File "/usr/lib/python2.7/dist-packages/gunicorn/app/base.py", line 67, in wsgi
    self.callable = self.load()
  File "/usr/lib/python2.7/dist-packages/gunicorn/app/wsgiapp.py", line 52, in load
    return self.load_wsgiapp()
  File "/usr/lib/python2.7/dist-packages/gunicorn/app/wsgiapp.py", line 41, in load_wsgiapp
    return util.import_app(self.app_uri)
  File "/usr/lib/python2.7/dist-packages/gunicorn/util.py", line 375, in import_app
    __import__(module)
  File "/home/pi/wanderpi/app.py", line 1, in <module>
    from controller.modules.home.geocode_utils import GeoCodeUtils
  File "/home/pi/wanderpi/controller/__init__.py", line 3, in <module>
    from flask import Flask
ImportError: No module named flask
[2021-09-01 14:30:00 +0000] [12188] [INFO] Worker exiting (pid: 12188)
[2021-09-01 14:30:00 +0000] [12189] [ERROR] Exception in worker process
Traceback (most recent call last):
  File "/usr/lib/python2.7/dist-packages/gunicorn/arbiter.py", line 583, in spawn_worker
    worker.init_process()
  File "/usr/lib/python2.7/dist-packages/gunicorn/workers/base.py", line 129, in init_process
    self.load_wsgi()
  File "/usr/lib/python2.7/dist-packages/gunicorn/workers/base.py", line 138, in load_wsgi
    self.wsgi = self.app.wsgi()
  File "/usr/lib/python2.7/dist-packages/gunicorn/app/base.py", line 67, in wsgi
    self.callable = self.load()
  File "/usr/lib/python2.7/dist-packages/gunicorn/app/wsgiapp.py", line 52, in load
    return self.load_wsgiapp()
  File "/usr/lib/python2.7/dist-packages/gunicorn/app/wsgiapp.py", line 41, in load_wsgiapp
    return util.import_app(self.app_uri)
  File "/usr/lib/python2.7/dist-packages/gunicorn/util.py", line 375, in import_app
    __import__(module)
  File "/home/pi/wanderpi/app.py", line 1, in <module>
    from controller.modules.home.geocode_utils import GeoCodeUtils
  File "/home/pi/wanderpi/controller/__init__.py", line 3, in <module>
    from flask import Flask
ImportError: No module named flask
[2021-09-01 14:30:00 +0000] [12189] [INFO] Worker exiting (pid: 12189)
[2021-09-01 14:30:00 +0000] [12190] [INFO] Booting worker with pid: 12190
[2021-09-01 14:30:00 +0000] [12191] [INFO] Booting worker with pid: 12191
[2021-09-01 14:30:00 +0000] [12190] [ERROR] Exception in worker process
Traceback (most recent call last):
  File "/usr/lib/python2.7/dist-packages/gunicorn/arbiter.py", line 583, in spawn_worker
    worker.init_process()
  File "/usr/lib/python2.7/dist-packages/gunicorn/workers/base.py", line 129, in init_process
    self.load_wsgi()
  File "/usr/lib/python2.7/dist-packages/gunicorn/workers/base.py", line 138, in load_wsgi
    self.wsgi = self.app.wsgi()
  File "/usr/lib/python2.7/dist-packages/gunicorn/app/base.py", line 67, in wsgi
    self.callable = self.load()
  File "/usr/lib/python2.7/dist-packages/gunicorn/app/wsgiapp.py", line 52, in load
    return self.load_wsgiapp()
  File "/usr/lib/python2.7/dist-packages/gunicorn/app/wsgiapp.py", line 41, in load_wsgiapp
    return util.import_app(self.app_uri)
  File "/usr/lib/python2.7/dist-packages/gunicorn/util.py", line 375, in import_app
    __import__(module)
  File "/home/pi/wanderpi/app.py", line 1, in <module>
    from controller.modules.home.geocode_utils import GeoCodeUtils
  File "/home/pi/wanderpi/controller/__init__.py", line 3, in <module>
    from flask import Flask
ImportError: No module named flask
[2021-09-01 14:30:00 +0000] [12190] [INFO] Worker exiting (pid: 12190)
[2021-09-01 14:31:00 +0100] [12201] [INFO] Starting gunicorn 20.1.0
[2021-09-01 14:31:00 +0100] [12201] [INFO] Listening at: unix:app.sock (12201)
[2021-09-01 14:31:00 +0100] [12201] [INFO] Using worker: sync
[2021-09-01 14:31:00 +0100] [12207] [INFO] Booting worker with pid: 12207
[2021-09-01 14:31:00 +0100] [12208] [INFO] Booting worker with pid: 12208
[2021-09-01 14:31:00 +0100] [12209] [INFO] Booting worker with pid: 12209
[2021-09-01 14:31:00 +0100] [12210] [INFO] Booting worker with pid: 12210
[2021-09-01 14:31:38 +0100] [12201] [INFO] Handling signal: int
[2021-09-01 14:31:38 +0100] [12210] [INFO] Worker exiting (pid: 12210)
[2021-09-01 14:31:38 +0100] [12207] [INFO] Worker exiting (pid: 12207)
[2021-09-01 14:31:38 +0100] [12208] [INFO] Worker exiting (pid: 12208)
[2021-09-01 14:31:38 +0100] [12209] [INFO] Worker exiting (pid: 12209)
[2021-09-01 14:31:39 +0100] [12201] [WARNING] Worker with pid 12207 was terminated due to signal 2
[2021-09-01 14:31:39 +0100] [12201] [WARNING] Worker with pid 12208 was terminated due to signal 2
[2021-09-01 14:31:39 +0100] [12201] [WARNING] Worker with pid 12209 was terminated due to signal 2
[2021-09-01 14:31:39 +0100] [12201] [WARNING] Worker with pid 12210 was terminated due to signal 2
[2021-09-01 14:31:39 +0100] [12201] [INFO] Shutting down: Master
[2021-09-01 14:31:51 +0100] [12213] [INFO] Starting gunicorn 20.1.0
[2021-09-01 14:31:51 +0100] [12213] [INFO] Listening at: unix:app.sock (12213)
[2021-09-01 14:31:51 +0100] [12213] [INFO] Using worker: sync
[2021-09-01 14:31:51 +0100] [12216] [INFO] Booting worker with pid: 12216
[2021-09-01 14:31:51 +0100] [12217] [INFO] Booting worker with pid: 12217
[2021-09-01 14:31:51 +0100] [12218] [INFO] Booting worker with pid: 12218
[2021-09-01 14:31:51 +0100] [12220] [INFO] Booting worker with pid: 12220
[2021-09-01 14:36:43 +0100] [12213] [INFO] Handling signal: int
[2021-09-01 14:36:43 +0100] [12216] [INFO] Worker exiting (pid: 12216)
[2021-09-01 14:36:43 +0100] [12218] [INFO] Worker exiting (pid: 12218)
[2021-09-01 14:36:43 +0100] [12217] [INFO] Worker exiting (pid: 12217)
[2021-09-01 14:36:43 +0100] [12220] [INFO] Worker exiting (pid: 12220)
[2021-09-01 14:36:43 +0100] [12213] [WARNING] Worker with pid 12216 was terminated due to signal 2
[2021-09-01 14:36:43 +0100] [12213] [WARNING] Worker with pid 12217 was terminated due to signal 2
[2021-09-01 14:36:43 +0100] [12213] [WARNING] Worker with pid 12220 was terminated due to signal 2
[2021-09-01 14:36:43 +0100] [12213] [WARNING] Worker with pid 12218 was terminated due to signal 2
[2021-09-01 14:36:43 +0100] [12213] [INFO] Shutting down: Master
[2021-09-01 14:38:18 +0100] [12466] [INFO] Starting gunicorn 20.1.0
[2021-09-01 14:38:18 +0100] [12466] [INFO] Listening at: unix:app.sock (12466)
[2021-09-01 14:38:18 +0100] [12466] [INFO] Using worker: sync
[2021-09-01 14:38:18 +0100] [12469] [INFO] Booting worker with pid: 12469
[2021-09-01 14:38:18 +0100] [12470] [INFO] Booting worker with pid: 12470
[2021-09-01 14:38:18 +0100] [12471] [INFO] Booting worker with pid: 12471
[2021-09-01 14:38:18 +0100] [12472] [INFO] Booting worker with pid: 12472
[2021-09-01 14:39:33 +0100] [12466] [INFO] Handling signal: int
[2021-09-01 14:39:33 +0100] [12470] [INFO] Worker exiting (pid: 12470)
[2021-09-01 14:39:33 +0100] [12469] [INFO] Worker exiting (pid: 12469)
[2021-09-01 14:39:33 +0100] [12472] [INFO] Worker exiting (pid: 12472)
[2021-09-01 14:39:33 +0100] [12471] [INFO] Worker exiting (pid: 12471)
[2021-09-01 14:39:34 +0100] [12466] [WARNING] Worker with pid 12470 was terminated due to signal 2
[2021-09-01 14:39:34 +0100] [12466] [WARNING] Worker with pid 12471 was terminated due to signal 2
[2021-09-01 14:39:34 +0100] [12466] [WARNING] Worker with pid 12472 was terminated due to signal 2
[2021-09-01 14:39:34 +0100] [12466] [WARNING] Worker with pid 12469 was terminated due to signal 2
[2021-09-01 14:39:34 +0100] [12466] [INFO] Shutting down: Master
[2021-09-01 14:42:05 +0000] [12564] [INFO] Starting gunicorn 19.9.0
[2021-09-01 14:42:05 +0000] [12564] [INFO] Listening at: unix:app.sock (12564)
[2021-09-01 14:42:05 +0000] [12564] [INFO] Using worker: sync
[2021-09-01 14:42:05 +0000] [12569] [INFO] Booting worker with pid: 12569
[2021-09-01 14:42:05 +0000] [12570] [INFO] Booting worker with pid: 12570
[2021-09-01 14:42:05 +0000] [12569] [ERROR] Exception in worker process
Traceback (most recent call last):
  File "/usr/lib/python2.7/dist-packages/gunicorn/arbiter.py", line 583, in spawn_worker
    worker.init_process()
  File "/usr/lib/python2.7/dist-packages/gunicorn/workers/base.py", line 129, in init_process
    self.load_wsgi()
  File "/usr/lib/python2.7/dist-packages/gunicorn/workers/base.py", line 138, in load_wsgi
    self.wsgi = self.app.wsgi()
  File "/usr/lib/python2.7/dist-packages/gunicorn/app/base.py", line 67, in wsgi
    self.callable = self.load()
  File "/usr/lib/python2.7/dist-packages/gunicorn/app/wsgiapp.py", line 52, in load
    return self.load_wsgiapp()
  File "/usr/lib/python2.7/dist-packages/gunicorn/app/wsgiapp.py", line 41, in load_wsgiapp
    return util.import_app(self.app_uri)
  File "/usr/lib/python2.7/dist-packages/gunicorn/util.py", line 375, in import_app
    __import__(module)
  File "/home/pi/wanderpi/app.py", line 1, in <module>
    from controller.modules.home.geocode_utils import GeoCodeUtils
  File "/home/pi/wanderpi/controller/__init__.py", line 3, in <module>
    from flask import Flask
ImportError: No module named flask
[2021-09-01 14:42:05 +0000] [12569] [INFO] Worker exiting (pid: 12569)
[2021-09-01 14:42:05 +0000] [12572] [INFO] Booting worker with pid: 12572
[2021-09-01 14:42:05 +0000] [12570] [ERROR] Exception in worker process
Traceback (most recent call last):
  File "/usr/lib/python2.7/dist-packages/gunicorn/arbiter.py", line 583, in spawn_worker
    worker.init_process()
  File "/usr/lib/python2.7/dist-packages/gunicorn/workers/base.py", line 129, in init_process
    self.load_wsgi()
  File "/usr/lib/python2.7/dist-packages/gunicorn/workers/base.py", line 138, in load_wsgi
    self.wsgi = self.app.wsgi()
  File "/usr/lib/python2.7/dist-packages/gunicorn/app/base.py", line 67, in wsgi
    self.callable = self.load()
  File "/usr/lib/python2.7/dist-packages/gunicorn/app/wsgiapp.py", line 52, in load
    return self.load_wsgiapp()
  File "/usr/lib/python2.7/dist-packages/gunicorn/app/wsgiapp.py", line 41, in load_wsgiapp
    return util.import_app(self.app_uri)
  File "/usr/lib/python2.7/dist-packages/gunicorn/util.py", line 375, in import_app
    __import__(module)
  File "/home/pi/wanderpi/app.py", line 1, in <module>
    from controller.modules.home.geocode_utils import GeoCodeUtils
  File "/home/pi/wanderpi/controller/__init__.py", line 3, in <module>
    from flask import Flask
ImportError: No module named flask
[2021-09-01 14:42:05 +0000] [12570] [INFO] Worker exiting (pid: 12570)
[2021-09-01 14:42:05 +0000] [12571] [INFO] Booting worker with pid: 12571
[2021-09-01 14:42:05 +0000] [12572] [ERROR] Exception in worker process
Traceback (most recent call last):
  File "/usr/lib/python2.7/dist-packages/gunicorn/arbiter.py", line 583, in spawn_worker
    worker.init_process()
  File "/usr/lib/python2.7/dist-packages/gunicorn/workers/base.py", line 129, in init_process
    self.load_wsgi()
  File "/usr/lib/python2.7/dist-packages/gunicorn/workers/base.py", line 138, in load_wsgi
    self.wsgi = self.app.wsgi()
  File "/usr/lib/python2.7/dist-packages/gunicorn/app/base.py", line 67, in wsgi
    self.callable = self.load()
  File "/usr/lib/python2.7/dist-packages/gunicorn/app/wsgiapp.py", line 52, in load
    return self.load_wsgiapp()
  File "/usr/lib/python2.7/dist-packages/gunicorn/app/wsgiapp.py", line 41, in load_wsgiapp
    return util.import_app(self.app_uri)
  File "/usr/lib/python2.7/dist-packages/gunicorn/util.py", line 375, in import_app
    __import__(module)
  File "/home/pi/wanderpi/app.py", line 1, in <module>
    from controller.modules.home.geocode_utils import GeoCodeUtils
  File "/home/pi/wanderpi/controller/__init__.py", line 3, in <module>
    from flask import Flask
ImportError: No module named flask
[2021-09-01 14:42:05 +0000] [12572] [INFO] Worker exiting (pid: 12572)
[2021-09-01 14:42:05 +0000] [12571] [ERROR] Exception in worker process
Traceback (most recent call last):
  File "/usr/lib/python2.7/dist-packages/gunicorn/arbiter.py", line 583, in spawn_worker
    worker.init_process()
  File "/usr/lib/python2.7/dist-packages/gunicorn/workers/base.py", line 129, in init_process
    self.load_wsgi()
  File "/usr/lib/python2.7/dist-packages/gunicorn/workers/base.py", line 138, in load_wsgi
    self.wsgi = self.app.wsgi()
  File "/usr/lib/python2.7/dist-packages/gunicorn/app/base.py", line 67, in wsgi
    self.callable = self.load()
  File "/usr/lib/python2.7/dist-packages/gunicorn/app/wsgiapp.py", line 52, in load
    return self.load_wsgiapp()
  File "/usr/lib/python2.7/dist-packages/gunicorn/app/wsgiapp.py", line 41, in load_wsgiapp
    return util.import_app(self.app_uri)
  File "/usr/lib/python2.7/dist-packages/gunicorn/util.py", line 375, in import_app
    __import__(module)
  File "/home/pi/wanderpi/app.py", line 1, in <module>
    from controller.modules.home.geocode_utils import GeoCodeUtils
  File "/home/pi/wanderpi/controller/__init__.py", line 3, in <module>
    from flask import Flask
ImportError: No module named flask
[2021-09-01 14:42:05 +0000] [12571] [INFO] Worker exiting (pid: 12571)
[2021-09-01 14:42:05 +0000] [12564] [INFO] Shutting down: Master
[2021-09-01 14:42:05 +0000] [12564] [INFO] Reason: Worker failed to boot.
[2021-09-01 14:42:25 +0000] [12602] [INFO] Starting gunicorn 19.9.0
[2021-09-01 14:42:25 +0000] [12602] [INFO] Listening at: unix:app.sock (12602)
[2021-09-01 14:42:25 +0000] [12602] [INFO] Using worker: sync
[2021-09-01 14:42:25 +0000] [12606] [INFO] Booting worker with pid: 12606
[2021-09-01 14:42:25 +0000] [12606] [ERROR] Exception in worker process
Traceback (most recent call last):
  File "/usr/lib/python2.7/dist-packages/gunicorn/arbiter.py", line 583, in spawn_worker
    worker.init_process()
  File "/usr/lib/python2.7/dist-packages/gunicorn/workers/base.py", line 129, in init_process
    self.load_wsgi()
  File "/usr/lib/python2.7/dist-packages/gunicorn/workers/base.py", line 138, in load_wsgi
    self.wsgi = self.app.wsgi()
  File "/usr/lib/python2.7/dist-packages/gunicorn/app/base.py", line 67, in wsgi
    self.callable = self.load()
  File "/usr/lib/python2.7/dist-packages/gunicorn/app/wsgiapp.py", line 52, in load
    return self.load_wsgiapp()
  File "/usr/lib/python2.7/dist-packages/gunicorn/app/wsgiapp.py", line 41, in load_wsgiapp
    return util.import_app(self.app_uri)
  File "/usr/lib/python2.7/dist-packages/gunicorn/util.py", line 375, in import_app
    __import__(module)
  File "/home/pi/wanderpi/app.py", line 1, in <module>
    from controller.modules.home.geocode_utils import GeoCodeUtils
  File "/home/pi/wanderpi/controller/__init__.py", line 3, in <module>
    from flask import Flask
ImportError: No module named flask
[2021-09-01 14:42:25 +0000] [12606] [INFO] Worker exiting (pid: 12606)
[2021-09-01 14:42:25 +0000] [12607] [INFO] Booting worker with pid: 12607
[2021-09-01 14:42:25 +0000] [12607] [ERROR] Exception in worker process
Traceback (most recent call last):
  File "/usr/lib/python2.7/dist-packages/gunicorn/arbiter.py", line 583, in spawn_worker
    worker.init_process()
  File "/usr/lib/python2.7/dist-packages/gunicorn/workers/base.py", line 129, in init_process
    self.load_wsgi()
  File "/usr/lib/python2.7/dist-packages/gunicorn/workers/base.py", line 138, in load_wsgi
    self.wsgi = self.app.wsgi()
  File "/usr/lib/python2.7/dist-packages/gunicorn/app/base.py", line 67, in wsgi
    self.callable = self.load()
  File "/usr/lib/python2.7/dist-packages/gunicorn/app/wsgiapp.py", line 52, in load
    return self.load_wsgiapp()
  File "/usr/lib/python2.7/dist-packages/gunicorn/app/wsgiapp.py", line 41, in load_wsgiapp
    return util.import_app(self.app_uri)
  File "/usr/lib/python2.7/dist-packages/gunicorn/util.py", line 375, in import_app
    __import__(module)
  File "/home/pi/wanderpi/app.py", line 1, in <module>
    from controller.modules.home.geocode_utils import GeoCodeUtils
  File "/home/pi/wanderpi/controller/__init__.py", line 3, in <module>
    from flask import Flask
ImportError: No module named flask
[2021-09-01 14:42:25 +0000] [12607] [INFO] Worker exiting (pid: 12607)
[2021-09-01 14:42:25 +0000] [12608] [INFO] Booting worker with pid: 12608
[2021-09-01 14:42:25 +0000] [12608] [ERROR] Exception in worker process
Traceback (most recent call last):
  File "/usr/lib/python2.7/dist-packages/gunicorn/arbiter.py", line 583, in spawn_worker
    worker.init_process()
  File "/usr/lib/python2.7/dist-packages/gunicorn/workers/base.py", line 129, in init_process
    self.load_wsgi()
  File "/usr/lib/python2.7/dist-packages/gunicorn/workers/base.py", line 138, in load_wsgi
    self.wsgi = self.app.wsgi()
  File "/usr/lib/python2.7/dist-packages/gunicorn/app/base.py", line 67, in wsgi
    self.callable = self.load()
  File "/usr/lib/python2.7/dist-packages/gunicorn/app/wsgiapp.py", line 52, in load
    return self.load_wsgiapp()
  File "/usr/lib/python2.7/dist-packages/gunicorn/app/wsgiapp.py", line 41, in load_wsgiapp
    return util.import_app(self.app_uri)
  File "/usr/lib/python2.7/dist-packages/gunicorn/util.py", line 375, in import_app
    __import__(module)
  File "/home/pi/wanderpi/app.py", line 1, in <module>
    from controller.modules.home.geocode_utils import GeoCodeUtils
  File "/home/pi/wanderpi/controller/__init__.py", line 3, in <module>
    from flask import Flask
ImportError: No module named flask
[2021-09-01 14:42:25 +0000] [12608] [INFO] Worker exiting (pid: 12608)
[2021-09-01 14:43:11 +0000] [12617] [INFO] Starting gunicorn 19.9.0
[2021-09-01 14:43:11 +0000] [12617] [INFO] Listening at: unix:app.sock (12617)
[2021-09-01 14:43:11 +0000] [12617] [INFO] Using worker: sync
[2021-09-01 14:43:11 +0000] [12621] [INFO] Booting worker with pid: 12621
[2021-09-01 14:43:11 +0000] [12622] [INFO] Booting worker with pid: 12622
[2021-09-01 14:43:11 +0000] [12621] [ERROR] Exception in worker process
Traceback (most recent call last):
  File "/usr/lib/python2.7/dist-packages/gunicorn/arbiter.py", line 583, in spawn_worker
    worker.init_process()
  File "/usr/lib/python2.7/dist-packages/gunicorn/workers/base.py", line 129, in init_process
    self.load_wsgi()
  File "/usr/lib/python2.7/dist-packages/gunicorn/workers/base.py", line 138, in load_wsgi
    self.wsgi = self.app.wsgi()
  File "/usr/lib/python2.7/dist-packages/gunicorn/app/base.py", line 67, in wsgi
    self.callable = self.load()
  File "/usr/lib/python2.7/dist-packages/gunicorn/app/wsgiapp.py", line 52, in load
    return self.load_wsgiapp()
  File "/usr/lib/python2.7/dist-packages/gunicorn/app/wsgiapp.py", line 41, in load_wsgiapp
    return util.import_app(self.app_uri)
  File "/usr/lib/python2.7/dist-packages/gunicorn/util.py", line 375, in import_app
    __import__(module)
  File "/home/pi/wanderpi/app.py", line 1, in <module>
    from controller.modules.home.geocode_utils import GeoCodeUtils
  File "/home/pi/wanderpi/controller/__init__.py", line 3, in <module>
    from flask import Flask
ImportError: No module named flask
[2021-09-01 14:43:11 +0000] [12621] [INFO] Worker exiting (pid: 12621)
[2021-09-01 14:43:11 +0000] [12622] [ERROR] Exception in worker process
Traceback (most recent call last):
  File "/usr/lib/python2.7/dist-packages/gunicorn/arbiter.py", line 583, in spawn_worker
    worker.init_process()
  File "/usr/lib/python2.7/dist-packages/gunicorn/workers/base.py", line 129, in init_process
    self.load_wsgi()
  File "/usr/lib/python2.7/dist-packages/gunicorn/workers/base.py", line 138, in load_wsgi
    self.wsgi = self.app.wsgi()
  File "/usr/lib/python2.7/dist-packages/gunicorn/app/base.py", line 67, in wsgi
    self.callable = self.load()
  File "/usr/lib/python2.7/dist-packages/gunicorn/app/wsgiapp.py", line 52, in load
    return self.load_wsgiapp()
  File "/usr/lib/python2.7/dist-packages/gunicorn/app/wsgiapp.py", line 41, in load_wsgiapp
    return util.import_app(self.app_uri)
  File "/usr/lib/python2.7/dist-packages/gunicorn/util.py", line 375, in import_app
    __import__(module)
  File "/home/pi/wanderpi/app.py", line 1, in <module>
    from controller.modules.home.geocode_utils import GeoCodeUtils
  File "/home/pi/wanderpi/controller/__init__.py", line 3, in <module>
    from flask import Flask
ImportError: No module named flask
[2021-09-01 14:43:11 +0000] [12622] [INFO] Worker exiting (pid: 12622)
[2021-09-01 14:43:11 +0000] [12623] [INFO] Booting worker with pid: 12623
[2021-09-01 14:43:11 +0000] [12623] [ERROR] Exception in worker process
Traceback (most recent call last):
  File "/usr/lib/python2.7/dist-packages/gunicorn/arbiter.py", line 583, in spawn_worker
    worker.init_process()
  File "/usr/lib/python2.7/dist-packages/gunicorn/workers/base.py", line 129, in init_process
    self.load_wsgi()
  File "/usr/lib/python2.7/dist-packages/gunicorn/workers/base.py", line 138, in load_wsgi
    self.wsgi = self.app.wsgi()
  File "/usr/lib/python2.7/dist-packages/gunicorn/app/base.py", line 67, in wsgi
    self.callable = self.load()
  File "/usr/lib/python2.7/dist-packages/gunicorn/app/wsgiapp.py", line 52, in load
    return self.load_wsgiapp()
  File "/usr/lib/python2.7/dist-packages/gunicorn/app/wsgiapp.py", line 41, in load_wsgiapp
    return util.import_app(self.app_uri)
  File "/usr/lib/python2.7/dist-packages/gunicorn/util.py", line 375, in import_app
    __import__(module)
  File "/home/pi/wanderpi/app.py", line 1, in <module>
    from controller.modules.home.geocode_utils import GeoCodeUtils
  File "/home/pi/wanderpi/controller/__init__.py", line 3, in <module>
    from flask import Flask
ImportError: No module named flask
[2021-09-01 14:43:11 +0000] [12623] [INFO] Worker exiting (pid: 12623)
[2021-09-01 14:43:11 +0000] [12617] [INFO] Shutting down: Master
[2021-09-01 14:43:11 +0000] [12617] [INFO] Reason: Worker failed to boot.
[2021-09-01 14:43:36 +0000] [12657] [INFO] Starting gunicorn 19.9.0
[2021-09-01 14:43:36 +0000] [12657] [INFO] Listening at: unix:app.sock (12657)
[2021-09-01 14:43:36 +0000] [12657] [INFO] Using worker: sync
[2021-09-01 14:43:36 +0000] [12661] [INFO] Booting worker with pid: 12661
[2021-09-01 14:43:36 +0000] [12661] [ERROR] Exception in worker process
Traceback (most recent call last):
  File "/usr/lib/python2.7/dist-packages/gunicorn/arbiter.py", line 583, in spawn_worker
    worker.init_process()
  File "/usr/lib/python2.7/dist-packages/gunicorn/workers/base.py", line 129, in init_process
    self.load_wsgi()
  File "/usr/lib/python2.7/dist-packages/gunicorn/workers/base.py", line 138, in load_wsgi
    self.wsgi = self.app.wsgi()
  File "/usr/lib/python2.7/dist-packages/gunicorn/app/base.py", line 67, in wsgi
    self.callable = self.load()
  File "/usr/lib/python2.7/dist-packages/gunicorn/app/wsgiapp.py", line 52, in load
    return self.load_wsgiapp()
  File "/usr/lib/python2.7/dist-packages/gunicorn/app/wsgiapp.py", line 41, in load_wsgiapp
    return util.import_app(self.app_uri)
  File "/usr/lib/python2.7/dist-packages/gunicorn/util.py", line 375, in import_app
    __import__(module)
  File "/home/pi/wanderpi/app.py", line 1, in <module>
    from controller.modules.home.geocode_utils import GeoCodeUtils
  File "/home/pi/wanderpi/controller/__init__.py", line 3, in <module>
    from flask import Flask
ImportError: No module named flask
[2021-09-01 14:43:36 +0000] [12661] [INFO] Worker exiting (pid: 12661)
[2021-09-01 14:43:36 +0000] [12662] [INFO] Booting worker with pid: 12662
[2021-09-01 14:43:36 +0000] [12663] [INFO] Booting worker with pid: 12663
[2021-09-01 14:43:36 +0000] [12662] [ERROR] Exception in worker process
Traceback (most recent call last):
  File "/usr/lib/python2.7/dist-packages/gunicorn/arbiter.py", line 583, in spawn_worker
    worker.init_process()
  File "/usr/lib/python2.7/dist-packages/gunicorn/workers/base.py", line 129, in init_process
    self.load_wsgi()
  File "/usr/lib/python2.7/dist-packages/gunicorn/workers/base.py", line 138, in load_wsgi
    self.wsgi = self.app.wsgi()
  File "/usr/lib/python2.7/dist-packages/gunicorn/app/base.py", line 67, in wsgi
    self.callable = self.load()
  File "/usr/lib/python2.7/dist-packages/gunicorn/app/wsgiapp.py", line 52, in load
    return self.load_wsgiapp()
  File "/usr/lib/python2.7/dist-packages/gunicorn/app/wsgiapp.py", line 41, in load_wsgiapp
    return util.import_app(self.app_uri)
  File "/usr/lib/python2.7/dist-packages/gunicorn/util.py", line 375, in import_app
    __import__(module)
  File "/home/pi/wanderpi/app.py", line 1, in <module>
    from controller.modules.home.geocode_utils import GeoCodeUtils
  File "/home/pi/wanderpi/controller/__init__.py", line 3, in <module>
    from flask import Flask
ImportError: No module named flask
[2021-09-01 14:43:36 +0000] [12662] [INFO] Worker exiting (pid: 12662)
[2021-09-01 14:43:36 +0000] [12663] [ERROR] Exception in worker process
Traceback (most recent call last):
  File "/usr/lib/python2.7/dist-packages/gunicorn/arbiter.py", line 583, in spawn_worker
    worker.init_process()
  File "/usr/lib/python2.7/dist-packages/gunicorn/workers/base.py", line 129, in init_process
    self.load_wsgi()
  File "/usr/lib/python2.7/dist-packages/gunicorn/workers/base.py", line 138, in load_wsgi
    self.wsgi = self.app.wsgi()
  File "/usr/lib/python2.7/dist-packages/gunicorn/app/base.py", line 67, in wsgi
    self.callable = self.load()
  File "/usr/lib/python2.7/dist-packages/gunicorn/app/wsgiapp.py", line 52, in load
    return self.load_wsgiapp()
  File "/usr/lib/python2.7/dist-packages/gunicorn/app/wsgiapp.py", line 41, in load_wsgiapp
    return util.import_app(self.app_uri)
  File "/usr/lib/python2.7/dist-packages/gunicorn/util.py", line 375, in import_app
    __import__(module)
  File "/home/pi/wanderpi/app.py", line 1, in <module>
    from controller.modules.home.geocode_utils import GeoCodeUtils
  File "/home/pi/wanderpi/controller/__init__.py", line 3, in <module>
    from flask import Flask
ImportError: No module named flask
[2021-09-01 14:43:36 +0000] [12663] [INFO] Worker exiting (pid: 12663)
[2021-09-01 14:43:36 +0000] [12664] [INFO] Booting worker with pid: 12664
[2021-09-01 14:43:36 +0000] [12664] [ERROR] Exception in worker process
Traceback (most recent call last):
  File "/usr/lib/python2.7/dist-packages/gunicorn/arbiter.py", line 583, in spawn_worker
    worker.init_process()
  File "/usr/lib/python2.7/dist-packages/gunicorn/workers/base.py", line 129, in init_process
    self.load_wsgi()
  File "/usr/lib/python2.7/dist-packages/gunicorn/workers/base.py", line 138, in load_wsgi
    self.wsgi = self.app.wsgi()
  File "/usr/lib/python2.7/dist-packages/gunicorn/app/base.py", line 67, in wsgi
    self.callable = self.load()
  File "/usr/lib/python2.7/dist-packages/gunicorn/app/wsgiapp.py", line 52, in load
    return self.load_wsgiapp()
  File "/usr/lib/python2.7/dist-packages/gunicorn/app/wsgiapp.py", line 41, in load_wsgiapp
    return util.import_app(self.app_uri)
  File "/usr/lib/python2.7/dist-packages/gunicorn/util.py", line 375, in import_app
    __import__(module)
  File "/home/pi/wanderpi/app.py", line 1, in <module>
    from controller.modules.home.geocode_utils import GeoCodeUtils
  File "/home/pi/wanderpi/controller/__init__.py", line 3, in <module>
    from flask import Flask
ImportError: No module named flask
[2021-09-01 14:43:36 +0000] [12664] [INFO] Worker exiting (pid: 12664)
[2021-09-01 14:45:30 +0000] [12753] [INFO] Starting gunicorn 19.9.0
[2021-09-01 14:45:30 +0000] [12753] [INFO] Listening at: unix:app.sock (12753)
[2021-09-01 14:45:30 +0000] [12753] [INFO] Using worker: sync
[2021-09-01 14:45:30 +0000] [12757] [INFO] Booting worker with pid: 12757
[2021-09-01 14:45:30 +0000] [12757] [ERROR] Exception in worker process
Traceback (most recent call last):
  File "/usr/lib/python2.7/dist-packages/gunicorn/arbiter.py", line 583, in spawn_worker
    worker.init_process()
  File "/usr/lib/python2.7/dist-packages/gunicorn/workers/base.py", line 129, in init_process
    self.load_wsgi()
  File "/usr/lib/python2.7/dist-packages/gunicorn/workers/base.py", line 138, in load_wsgi
    self.wsgi = self.app.wsgi()
  File "/usr/lib/python2.7/dist-packages/gunicorn/app/base.py", line 67, in wsgi
    self.callable = self.load()
  File "/usr/lib/python2.7/dist-packages/gunicorn/app/wsgiapp.py", line 52, in load
    return self.load_wsgiapp()
  File "/usr/lib/python2.7/dist-packages/gunicorn/app/wsgiapp.py", line 41, in load_wsgiapp
    return util.import_app(self.app_uri)
  File "/usr/lib/python2.7/dist-packages/gunicorn/util.py", line 375, in import_app
    __import__(module)
  File "/home/pi/wanderpi/app.py", line 1, in <module>
    from controller.modules.home.geocode_utils import GeoCodeUtils
  File "/home/pi/wanderpi/controller/__init__.py", line 3, in <module>
    from flask import Flask
ImportError: No module named flask
[2021-09-01 14:45:30 +0000] [12757] [INFO] Worker exiting (pid: 12757)
[2021-09-01 14:45:30 +0000] [12758] [INFO] Booting worker with pid: 12758
[2021-09-01 14:45:30 +0000] [12758] [ERROR] Exception in worker process
Traceback (most recent call last):
  File "/usr/lib/python2.7/dist-packages/gunicorn/arbiter.py", line 583, in spawn_worker
    worker.init_process()
  File "/usr/lib/python2.7/dist-packages/gunicorn/workers/base.py", line 129, in init_process
    self.load_wsgi()
  File "/usr/lib/python2.7/dist-packages/gunicorn/workers/base.py", line 138, in load_wsgi
    self.wsgi = self.app.wsgi()
  File "/usr/lib/python2.7/dist-packages/gunicorn/app/base.py", line 67, in wsgi
    self.callable = self.load()
  File "/usr/lib/python2.7/dist-packages/gunicorn/app/wsgiapp.py", line 52, in load
    return self.load_wsgiapp()
  File "/usr/lib/python2.7/dist-packages/gunicorn/app/wsgiapp.py", line 41, in load_wsgiapp
    return util.import_app(self.app_uri)
  File "/usr/lib/python2.7/dist-packages/gunicorn/util.py", line 375, in import_app
    __import__(module)
  File "/home/pi/wanderpi/app.py", line 1, in <module>
    from controller.modules.home.geocode_utils import GeoCodeUtils
  File "/home/pi/wanderpi/controller/__init__.py", line 3, in <module>
    from flask import Flask
ImportError: No module named flask
[2021-09-01 14:45:30 +0000] [12758] [INFO] Worker exiting (pid: 12758)
[2021-09-01 14:45:30 +0000] [12759] [INFO] Booting worker with pid: 12759
[2021-09-01 14:45:30 +0000] [12759] [ERROR] Exception in worker process
Traceback (most recent call last):
  File "/usr/lib/python2.7/dist-packages/gunicorn/arbiter.py", line 583, in spawn_worker
    worker.init_process()
  File "/usr/lib/python2.7/dist-packages/gunicorn/workers/base.py", line 129, in init_process
    self.load_wsgi()
  File "/usr/lib/python2.7/dist-packages/gunicorn/workers/base.py", line 138, in load_wsgi
    self.wsgi = self.app.wsgi()
  File "/usr/lib/python2.7/dist-packages/gunicorn/app/base.py", line 67, in wsgi
    self.callable = self.load()
  File "/usr/lib/python2.7/dist-packages/gunicorn/app/wsgiapp.py", line 52, in load
    return self.load_wsgiapp()
  File "/usr/lib/python2.7/dist-packages/gunicorn/app/wsgiapp.py", line 41, in load_wsgiapp
    return util.import_app(self.app_uri)
  File "/usr/lib/python2.7/dist-packages/gunicorn/util.py", line 375, in import_app
    __import__(module)
  File "/home/pi/wanderpi/app.py", line 1, in <module>
    from controller.modules.home.geocode_utils import GeoCodeUtils
  File "/home/pi/wanderpi/controller/__init__.py", line 3, in <module>
    from flask import Flask
ImportError: No module named flask
[2021-09-01 14:45:30 +0000] [12759] [INFO] Worker exiting (pid: 12759)
[2021-09-01 14:45:30 +0000] [12760] [INFO] Booting worker with pid: 12760
[2021-09-01 14:45:30 +0000] [12760] [ERROR] Exception in worker process
Traceback (most recent call last):
  File "/usr/lib/python2.7/dist-packages/gunicorn/arbiter.py", line 583, in spawn_worker
    worker.init_process()
  File "/usr/lib/python2.7/dist-packages/gunicorn/workers/base.py", line 129, in init_process
    self.load_wsgi()
  File "/usr/lib/python2.7/dist-packages/gunicorn/workers/base.py", line 138, in load_wsgi
    self.wsgi = self.app.wsgi()
  File "/usr/lib/python2.7/dist-packages/gunicorn/app/base.py", line 67, in wsgi
    self.callable = self.load()
  File "/usr/lib/python2.7/dist-packages/gunicorn/app/wsgiapp.py", line 52, in load
    return self.load_wsgiapp()
  File "/usr/lib/python2.7/dist-packages/gunicorn/app/wsgiapp.py", line 41, in load_wsgiapp
    return util.import_app(self.app_uri)
  File "/usr/lib/python2.7/dist-packages/gunicorn/util.py", line 375, in import_app
    __import__(module)
  File "/home/pi/wanderpi/app.py", line 1, in <module>
    from controller.modules.home.geocode_utils import GeoCodeUtils
  File "/home/pi/wanderpi/controller/__init__.py", line 3, in <module>
    from flask import Flask
ImportError: No module named flask
[2021-09-01 14:45:30 +0000] [12760] [INFO] Worker exiting (pid: 12760)
[2021-09-01 14:45:57 +0000] [12792] [INFO] Starting gunicorn 19.9.0
[2021-09-01 14:45:57 +0000] [12792] [INFO] Listening at: unix:app.sock (12792)
[2021-09-01 14:45:57 +0000] [12792] [INFO] Using worker: sync
[2021-09-01 14:45:57 +0000] [12796] [INFO] Booting worker with pid: 12796
[2021-09-01 14:45:57 +0000] [12796] [ERROR] Exception in worker process
Traceback (most recent call last):
  File "/usr/lib/python2.7/dist-packages/gunicorn/arbiter.py", line 583, in spawn_worker
    worker.init_process()
  File "/usr/lib/python2.7/dist-packages/gunicorn/workers/base.py", line 129, in init_process
    self.load_wsgi()
  File "/usr/lib/python2.7/dist-packages/gunicorn/workers/base.py", line 138, in load_wsgi
    self.wsgi = self.app.wsgi()
  File "/usr/lib/python2.7/dist-packages/gunicorn/app/base.py", line 67, in wsgi
    self.callable = self.load()
  File "/usr/lib/python2.7/dist-packages/gunicorn/app/wsgiapp.py", line 52, in load
    return self.load_wsgiapp()
  File "/usr/lib/python2.7/dist-packages/gunicorn/app/wsgiapp.py", line 41, in load_wsgiapp
    return util.import_app(self.app_uri)
  File "/usr/lib/python2.7/dist-packages/gunicorn/util.py", line 375, in import_app
    __import__(module)
  File "/home/pi/wanderpi/app.py", line 1, in <module>
    from controller.modules.home.geocode_utils import GeoCodeUtils
  File "/home/pi/wanderpi/controller/__init__.py", line 3, in <module>
    from flask import Flask
ImportError: No module named flask
[2021-09-01 14:45:57 +0000] [12796] [INFO] Worker exiting (pid: 12796)
[2021-09-01 14:45:57 +0000] [12797] [INFO] Booting worker with pid: 12797
[2021-09-01 14:45:57 +0000] [12797] [ERROR] Exception in worker process
Traceback (most recent call last):
  File "/usr/lib/python2.7/dist-packages/gunicorn/arbiter.py", line 583, in spawn_worker
    worker.init_process()
  File "/usr/lib/python2.7/dist-packages/gunicorn/workers/base.py", line 129, in init_process
    self.load_wsgi()
  File "/usr/lib/python2.7/dist-packages/gunicorn/workers/base.py", line 138, in load_wsgi
    self.wsgi = self.app.wsgi()
  File "/usr/lib/python2.7/dist-packages/gunicorn/app/base.py", line 67, in wsgi
    self.callable = self.load()
  File "/usr/lib/python2.7/dist-packages/gunicorn/app/wsgiapp.py", line 52, in load
    return self.load_wsgiapp()
  File "/usr/lib/python2.7/dist-packages/gunicorn/app/wsgiapp.py", line 41, in load_wsgiapp
    return util.import_app(self.app_uri)
  File "/usr/lib/python2.7/dist-packages/gunicorn/util.py", line 375, in import_app
    __import__(module)
  File "/home/pi/wanderpi/app.py", line 1, in <module>
    from controller.modules.home.geocode_utils import GeoCodeUtils
  File "/home/pi/wanderpi/controller/__init__.py", line 3, in <module>
    from flask import Flask
ImportError: No module named flask
[2021-09-01 14:45:57 +0000] [12797] [INFO] Worker exiting (pid: 12797)
[2021-09-01 14:45:57 +0000] [12792] [INFO] Shutting down: Master
[2021-09-01 14:45:57 +0000] [12792] [INFO] Reason: Worker failed to boot.
[2021-09-01 14:46:13 +0100] [12806] [INFO] Starting gunicorn 20.1.0
[2021-09-01 14:46:13 +0100] [12806] [INFO] Listening at: unix:app.sock (12806)
[2021-09-01 14:46:13 +0100] [12806] [INFO] Using worker: sync
[2021-09-01 14:46:13 +0100] [12809] [INFO] Booting worker with pid: 12809
[2021-09-01 14:46:13 +0100] [12810] [INFO] Booting worker with pid: 12810
[2021-09-01 14:46:13 +0100] [12811] [INFO] Booting worker with pid: 12811
[2021-09-01 14:46:13 +0100] [12812] [INFO] Booting worker with pid: 12812
[2021-09-01 15:00:56 +0100] [12806] [INFO] Handling signal: int
[2021-09-01 15:00:56 +0100] [12812] [INFO] Worker exiting (pid: 12812)
[2021-09-01 15:00:56 +0100] [12809] [INFO] Worker exiting (pid: 12809)
[2021-09-01 15:00:56 +0100] [12811] [INFO] Worker exiting (pid: 12811)
[2021-09-01 15:00:56 +0100] [12810] [INFO] Worker exiting (pid: 12810)
[2021-09-01 15:00:56 +0100] [12806] [WARNING] Worker with pid 12810 was terminated due to signal 2
[2021-09-01 15:00:56 +0100] [12806] [WARNING] Worker with pid 12811 was terminated due to signal 2
[2021-09-01 15:00:56 +0100] [12806] [WARNING] Worker with pid 12812 was terminated due to signal 2
[2021-09-01 15:00:56 +0100] [12806] [WARNING] Worker with pid 12809 was terminated due to signal 2
[2021-09-01 15:00:56 +0100] [12806] [INFO] Shutting down: Master
